<?xml version="1.0"?>

<!-- XML namespaces -->
<robot xmlns:sensor="http://playerstage.sourceforge.net/gazebo/xmlschema/#sensor"
       xmlns:controller="http://playerstage.sourceforge.net/gazebo/xmlschema/#controller"
       xmlns:interface="http://playerstage.sourceforge.net/gazebo/xmlschema/#interface"
       xmlns:xacro="http://ros.org/wiki/xacro" 
	   name="kinectbot">

  <include filename="$(find pi_kinectbot)/urdf/turtlebot_hardware.xacro" />
  
  <material name="Green">
    <color rgba="0.0 0.8 0.0 1.0"/>
  </material>

  <property name="M_PI" value="3.14159"/>
  <property name="SCALE" value="0.0254"/>
  <property name="M_SCALE" value="0.001"/>
  <property name="base_x" value="0.33" />
  <property name="base_y" value="0.33" />

	   
 	<!-- ============================  A Few Color Macros  ============================ -->
	
	<xacro:macro name="black">
		<material name="black">
			<color rgba="0.1 0.1 0.1 1.0"/>
		</material>
	</xacro:macro>
	
	<xacro:macro name="white">
		<material name="white">
			<color rgba="1.0 1.0 1.0 1.0"/>
		</material>
	</xacro:macro>
	
	<xacro:macro name="grey1">
		<material name="grey1">
			<color rgba="0.75 0.75 0.75 1.0"/>
		</material>
	</xacro:macro>
	
	<xacro:macro name="grey2">
		<material name="grey2">
			<color rgba="0.6 0.6 0.6 1.0"/>
		</material>
	</xacro:macro>
	
	<xacro:macro name="grey3">
		<material name="grey3">
			<color rgba="0.8 0.8 0.8 1.0"/>
		</material>
	</xacro:macro>

	<xacro:macro name="ax12_color">
		<material name="ax12_color">
			<color rgba="0.2 0.2 0.2 1.0"/>
		</material>
	</xacro:macro>
	
	<xacro:macro name="bracket_color">
		<material name="bracket_color">
			<color rgba="0.9 0.9 0.9 1.0"/>
		</material>
	</xacro:macro>
	
 	<!-- ============================   A Few Shape Macros  ============================ -->
	
	<xacro:macro name="ax12" params="name xyz rpy">
		<link name="${name}">
			<visual>
				<origin xyz="${xyz}" rpy="${rpy}" />
				<geometry>
					<box size="0.05 0.032 0.038" />
				</geometry>
				<xacro:ax12_color />
             </visual>
             <collision>
				<origin xyz="${xyz}" rpy="${rpy}" />
					<geometry>
						<box size="0.05 0.032 0.038" />
					</geometry>
             </collision>
             <xacro:default_inertial mass="0.055" />   
        </link>
        <xacro:default_gazebo name="${name}" material="Gazebo/FlatBlack" />
	</xacro:macro>
	
	<xacro:macro name="bracket1" params="name xyz rpy">
		<link name="${name}">
			<visual>
				<origin xyz="${xyz}" rpy="${rpy}" />
				<geometry>
					<box size="0.05 0.025 0.038" />	
				</geometry>
				<xacro:bracket_color />
             </visual>
             <collision>
				<origin xyz="${xyz}" rpy="${rpy}" />
					<geometry>
						<box size="0.05 0.025 0.038" />
					</geometry>
             </collision>
             <xacro:default_inertial mass="0.02" />   
        </link>
        <xacro:default_gazebo name="${name}" material="Gazebo/WhiteEmissive" />
	</xacro:macro>
	
	<xacro:macro name="bracket2" params="name xyz rpy">
		<link name="${name}">
			<visual>
				<origin xyz="${xyz}" rpy="${rpy}" />
				<geometry>
					<box size="0.05 0.032 0.005" />	
				</geometry>
				<xacro:bracket_color />
             </visual>
             <collision>
				<origin xyz="${xyz}" rpy="${rpy}" />
					<geometry>
					<box size="0.05 0.032 0.005" />	
					</geometry>
             </collision>
             <xacro:default_inertial mass="0.01" />   
        </link>
        <xacro:default_gazebo name="${name}" material="Gazebo/WhiteEmissive" />
	</xacro:macro>
	
	<xacro:macro name="my_box" params="name lwh xyz rpy mass material *rviz_color">
		<link name="${name}">
			<visual>
				<origin xyz="${xyz}" rpy="${rpy}" />
				<geometry>
					<box size="${lwh}" />
				</geometry>
			    <xacro:insert_block name="rviz_color" />             
             </visual>
             <collision>
				<origin xyz="${xyz}" rpy="${rpy}" />
					<geometry>
						<box size="${lwh}" />
					</geometry>
             </collision>
             <xacro:default_inertial mass="${mass}" />   
        </link>
        <xacro:default_gazebo name="${name}" material="${material}" />
	</xacro:macro>

	<xacro:macro name="my_cylinder" params="name l r xyz rpy mass material *rviz_color">
		<link name="${name}">
			<visual>	
				<origin xyz="${xyz}" rpy="${rpy}" />
				<geometry>
					<cylinder length="${l}" radius="${r}" />
				</geometry>
            	<xacro:insert_block name="rviz_color" />
            </visual>
            <collision>
				<origin xyz="${xyz}" rpy="${rpy}" />
					<geometry>
						<cylinder length="${l}" radius="${r}" />
					</geometry>
            </collision>
            <xacro:default_inertial mass="${mass}" />
        </link>
        <xacro:default_gazebo name="${name}" material="${material}" />
	</xacro:macro>

    <xacro:macro name="default_inertial" params="mass">
		<inertial>
			<mass value="${mass}" />
			<inertia ixx="0.001" ixy="0.0" ixz="0.0"
                     iyy="0.001" iyz="0.0"
                     izz="0.001" />                     
			</inertial>
    </xacro:macro>
    
    <xacro:macro name="default_gazebo" params="name material">
 		<gazebo reference="${name}">
			<material>${material}</material>
			<selfCollide>false</selfCollide>
			<turnGravityOff>true</turnGravityOff>
		</gazebo>
    </xacro:macro>
    
 	<!-- ============================   Link Definitions  ============================ -->

    <link name="base_footprint">
        <inertial>
            <mass value="0.0001" />
            <origin xyz="0 0 0" />
            <inertia ixx="0.0001" ixy="0.0" ixz="0.0"
                     iyy="0.0001" iyz="0.0" 
                     izz="0.0001" />
        </inertial>
        <visual>
            <origin xyz="0 0 0" rpy="0 0 0" />
            <geometry>
                <box size="0.001 0.001 0.001" />
            </geometry>
            <material name="Green" />
        </visual>

        <collision>
            <origin xyz="0 0 0.017" rpy="0 0 0" />
            <geometry>
              <box size="0.001 0.001 0.001" />
            </geometry>
        </collision>
    </link>

    <link name="base_link">
      <inertial>
        <mass value="12" />
        <origin xyz="0 0 0.017" />
        <inertia ixx="1.0" ixy="0.0" ixz="0.0"
                 iyy="1.0" iyz="0.0"
                 izz="1.0" />
      </inertial>
      
      <visual>
        <origin xyz=" 0 0 0 " rpy="0 0 0" />
        <geometry>
          <mesh filename="package://turtlebot_urdf/meshes/68-04545_iRobot_Create.dae" scale="${SCALE} ${SCALE} ${SCALE}"/>
        </geometry>
      </visual>
      
      <collision>
        <origin xyz="0.0 0.0 0.0" rpy="0 0 0" />
        <geometry>
          <mesh filename="package://turtlebot_urdf/meshes/68-04545_iRobot_Create.STL"/>
        </geometry>
      </collision>
    </link>
    
    <turtlebot_standoff_2in parent="base_link" number="0" x_loc="-0.00254" y_loc="0.1114679" z_loc="0.061"/>
    <turtlebot_standoff_2in parent="base_link" number="1" x_loc="-0.00254" y_loc="-0.1114679" z_loc="0.061"/>
    <turtlebot_standoff_2in parent="base_link" number="2" x_loc="-0.07239" y_loc="-0.1114679" z_loc="0.061"/>
    <turtlebot_standoff_2in parent="base_link" number="3" x_loc="-0.07239" y_loc="0.1114679" z_loc="0.061"/>

    <joint name="gyro_joint" type="fixed">
      <origin xyz="0 0 0.04" rpy="0 0 0" />
      <parent link="base_link" />
      <child link="gyro_link" />
    </joint>
    
    <link name="gyro_link">
      <visual>
        <geometry>
          <box size="0.02 0.035 0.002" />
        </geometry>
        <material name="Green" />
      </visual>
      <inertial>
        <mass value="0.0001" />
        <origin xyz="0 0 0" />
        <inertia ixx="0.0001" ixy="0.0" ixz="0.0"
                 iyy="0.0001" iyz="0.0"
                 izz="0.0001" />
      </inertial>
    </link>


    <joint name="plate_0_joint" type="fixed">
      <origin xyz="-0.04334 0 0.115" rpy="0 0 0" />
      <parent link="base_link"/>
      <child link="plate_0_link" />
    </joint>

	<link name="plate_0_link">
	  <inertial>
	    <mass value="0.2" />
	    <origin xyz="0 0 0" />
	    <inertia ixx="1.0" ixy="0.0" ixz="0.0"
	             iyy="1.0" iyz="0.0"
	             izz="1.0" />
	  </inertial>
	  
	  <visual>
	    <origin xyz=" 0 0 0 " rpy="0 0 0" />
	    <geometry>
	      <mesh filename="package://turtlebot_urdf/meshes/plate_0_logo.dae" scale="${M_SCALE} ${M_SCALE} ${M_SCALE}"/>
	    </geometry>
	  </visual>
	  
	  <collision>
	    <origin xyz="0.0 0.0 0.0" rpy="0 0 0" />
	    <geometry>
	      <mesh filename="package://turtlebot_urdf/meshes/plate_0_logo.dae"/>
	    </geometry>
	  </collision>
	</link>
	
    <turtlebot_standoff_2in_b parent="standoff_2in_0_link" number="0" x_loc="0" y_loc="0" z_loc="0.051"/>
    <turtlebot_standoff_2in_b parent="standoff_2in_1_link" number="1" x_loc="0" y_loc="0" z_loc="0.051"/>
    <turtlebot_standoff_2in_b parent="standoff_2in_2_link" number="2" x_loc="0" y_loc="0" z_loc="0.051"/>
    <turtlebot_standoff_2in_b parent="standoff_2in_3_link" number="3" x_loc="0" y_loc="0" z_loc="0.051"/>

    <joint name="plate_1_joint" type="fixed">
      <origin xyz="0 0 0.05" rpy="0 0 0" />
      <parent link="plate_0_link"/>
      <child link="plate_1_link" />
    </joint>

    <link name="plate_1_link">
      <inertial>
        <mass value="12" />
        <origin xyz="0 0 0" />
        <inertia ixx="1.0" ixy="0.0" ixz="0.0"
                 iyy="1.0" iyz="0.0"
                 izz="1.0" />
      </inertial>
      
      <visual>
        <origin xyz=" 0 0 0 " rpy="0 0 0" />
        <geometry>
          <mesh filename="package://turtlebot_urdf/meshes/plate_0_logo.dae" scale="${M_SCALE} ${M_SCALE} ${M_SCALE}"/>
        </geometry>
      </visual>
      
      <collision>
        <origin xyz="0.0 0.0 0.0" rpy="0 0 0" />
        <geometry>
          <mesh filename="package://turtlebot_urdf/meshes/plate_1_logo.dae"/>
        </geometry>
      </collision>
    </link>
	
	<xacro:my_box name="base_laser_bottom" lwh="0.05 0.05 0.035" xyz="0 0 0" rpy="0 0 0" mass="0.1" material="Gazebo/FlatBlack">
		<xacro:black />
	</xacro:my_box>
	
	<xacro:my_cylinder name="base_laser" l="0.035" r="0.025" xyz="0 0 0" rpy="0 0 0" mass="0.1" material="Gazebo/Grey">
		<xacro:black />
	</xacro:my_cylinder>

	<xacro:ax12 name="head_pan_link" xyz="0 0 0" rpy="0 0 0">
	</xacro:ax12>
	
	<xacro:bracket2 name="pan_tilt_bracket" xyz="0 0 0" rpy="0 0 0">
	</xacro:bracket2>
	
	<xacro:ax12 name="head_tilt_link" xyz="0 0 0" rpy="0 1.57 0">
	</xacro:ax12>
	
	<xacro:my_box name="neck_link" lwh="0.028 0.048 0.068" xyz="0 0 0.02" rpy="0 0 0" mass="0.05" material="Gazebo/WhiteEmissive">
		<xacro:bracket_color />
	</xacro:my_box>
	
    <link name="kinect_link">
      <inertial>
        <mass value="1.0" />
        <origin xyz="0 0 0" />
        <inertia ixx="1.0" ixy="0.0" ixz="0.0"
                 iyy="1.0" iyz="0.0"
                 izz="1.0" />
      </inertial>

      <visual>
        <origin xyz=" 0 0 0 " rpy="0 0 0" />
        <geometry>
          <mesh filename="package://turtlebot_urdf/meshes/68-04546_Kinect_Sensor.3ds" scale="${M_SCALE} ${M_SCALE} ${M_SCALE}"/>
        </geometry>
      </visual>

      <collision>
        <origin xyz="0.0 0.0 0.0" rpy="0 0 0" />
        <geometry>
          <mesh filename="package://turtlebot_urdf/meshes/68-04546_Kinect_Sensor.3ds"/>
          </geometry>
      </collision>

    </link>

    <joint name="kinect_depth_joint" type="fixed">
      <origin xyz="0 0.018 0" rpy="0 0 0" />
      <parent link="kinect_link" />
      <child link="kinect_depth_frame" />
    </joint>
    
    <link name="kinect_depth_frame">
      <inertial>
        <mass value="0.0001" />
        <origin xyz="0 0 0" />
        <inertia ixx="0.0001" ixy="0.0" ixz="0.0"
                 iyy="0.0001" iyz="0.0"
                 izz="0.0001" />
      </inertial>
    </link>
    
    <joint name="kinect_depth_optical_joint" type="fixed">
      <origin xyz="0 0 0" rpy="${-M_PI/2} 0 ${-M_PI/2}" />
      <parent link="kinect_depth_frame" />
      <child link="kinect_depth_optical_frame" />
    </joint>
    
    <link name="kinect_depth_optical_frame">
      <inertial>
        <mass value="0.0001" />
        <origin xyz="0 0 0" />
        <inertia ixx="0.0001" ixy="0.0" ixz="0.0"
                 iyy="0.0001" iyz="0.0"
                 izz="0.0001" />
      </inertial>
    </link>
    
    
    <joint name="kinect_rgb_joint" type="fixed">
      <origin xyz="0 -0.005 0" rpy="0 0 0" />
      <parent link="kinect_link" />
      <child link="kinect_rgb_frame" />
    </joint>
    
    <link name="kinect_rgb_frame">
      <inertial>
        <mass value="0.0001" />
        <origin xyz="0 0 0" />
        <inertia ixx="0.0001" ixy="0.0" ixz="0.0"
                 iyy="0.0001" iyz="0.0"
                 izz="0.0001" />
      </inertial>
    </link>
    

    <joint name="kinect_rgb_optical_joint" type="fixed">
      <origin xyz="0 0 0" rpy="${-M_PI/2} 0 ${-M_PI/2}" />
      <parent link="kinect_rgb_frame" />
      <child link="kinect_rgb_optical_frame" />
    </joint>
    
    <link name="kinect_rgb_optical_frame">
      <inertial>
        <mass value="0.0001" />
        <origin xyz="0 0 0" />
        <inertia ixx="0.0001" ixy="0.0" ixz="0.0"
                 iyy="0.0001" iyz="0.0"
                 izz="0.0001" />
      </inertial>
    </link>
	
	<xacro:my_cylinder name="left_eye_link" l="0.005" r="0.01" xyz="0 0 00" rpy="0 1.57 0" mass="0.001" material="Gazebo/WhiteEmissive">
		<xacro:grey3 />
	</xacro:my_cylinder>
	
	<xacro:my_cylinder name="right_eye_link" l="0.005" r="0.01" xyz="0 0 00" rpy="0 1.57 0" mass="0.001" material="Gazebo/WhiteEmissive">
		<xacro:grey3 />
	</xacro:my_cylinder>
	
	<xacro:my_box name="hair_link" lwh="0.005 0.04 0.05" xyz="0 0 0" rpy="0 0 0" mass="0.05" material="Gazebo/WhiteEmissive">
		<xacro:grey2 />
	</xacro:my_box>
	
	<!-- =================== Joint Definitions ==================== -->

    <joint name="base_footprint_joint" type="fixed">
        <!-- NB: While you would think this would make it go up, it is oddly reversed.
             This moves the joint to 0,0,0 where we want it for rviz, etc. -->
        <origin xyz="0 0 0.017" rpy="0 0 0" />        
        <parent link="base_footprint"/>
        <child link="base_link" />
    </joint>
    
 	<joint name="base_laser_bottom_joint" type="fixed">
    	<parent link="base_link" />
    	<child link="base_laser_bottom" />
    	<origin xyz="0.07 0 0.086" rpy="0 0 0" />
	</joint>
	
	<joint name="base_laser_joint" type="fixed">
    	<parent link="base_laser_bottom" />
    	<child link="base_laser" />
    	<origin xyz="0 0 0.035" rpy="0 0 0" />
	</joint>

	<joint name="head_pan_servo" type="fixed">
    	<parent link="plate_1_link" />
    	<child link="head_pan_link" />
    	<origin xyz="-0.088 0 0.0225" rpy="0 0 0" />
	</joint>
	
	<joint name="pan_tilt_bracket" type="fixed">
    	<parent link="head_pan_link" />
    	<child link="pan_tilt_bracket" />
    	<origin xyz="0 0 0.0215" rpy="0 0 0" />
	</joint>
	
	<joint name="head_pan_joint" type="revolute">
    	<parent link="pan_tilt_bracket" />
    	<child link="head_tilt_link" />
    	<origin xyz="0 0 0.0275" rpy="0 0 0" />
    	<axis xyz="0 0 1" />
    	<limit lower="-3.1416" upper="3.1416" effort="10" velocity="3" />
      	<dynamics damping="0.0"/>
	</joint>
  	
 	<joint name="head_tilt_joint" type="revolute">
    	<parent link="head_tilt_link" />
    	<child link="neck_link" />
    	<origin xyz="0 0 0.02" rpy="0 0 0" />
    	<axis xyz="0 -1 0" />
    	<limit lower="-1.57" upper="1.57" effort="10" velocity="3" />
      	<dynamics damping="0.0"/>
	</joint>
  	
 	<joint name="neck_joint" type="fixed">
    	<parent link="neck_link" />
    	<child link="kinect_link" />
    	<origin xyz="0.032 0 0.105" rpy="0 0 0" />
	</joint>
	
	<joint name="left_eye_joint" type="fixed">
    	<parent link="kinect_link" />
    	<child link="left_eye_link" />
    	<origin xyz="-0.005 0.04 0" rpy="0 0 0" />
	</joint>
	
	<joint name="right_eye_joint" type="fixed">
    	<parent link="kinect_link" />
    	<child link="right_eye_link" />
    	<origin xyz="-0.005 -0.04 0" rpy="0 0 0" />
	</joint>
	
	<joint name="hair_joint" type="fixed">
    	<parent link="kinect_link" />
    	<child link="hair_link" />
    	<origin xyz="-0.05 0 0.0425" rpy="0 0 0" />
	</joint>
	
	<gazebo reference="kinectbot">
  	</gazebo>
</robot>

