<?xml version="1.0"?>

<!-- XML namespaces -->
<robot xmlns:sensor="http://playerstage.sourceforge.net/gazebo/xmlschema/#sensor"
       xmlns:controller="http://playerstage.sourceforge.net/gazebo/xmlschema/#controller"
       xmlns:interface="http://playerstage.sourceforge.net/gazebo/xmlschema/#interface"
       xmlns:xacro="http://ros.org/wiki/xacro" 
	   name="single_joint">
       
  <gazebo reference="base">
    <material>Gazebo/GrassFloor</material>
  </gazebo>
  <link name="world"/>
  <joint name="link_joint" type="fixed">
    <axis xyz="0 0 1"/>
    <parent link="world"/>
    <origin rpy="0 0 0" xyz="0 0 1"/>
    <child link="link"/>
    <dynamics damping="0.1"/>
  </joint>
  <joint name="link2_joint" type="continuous">
    <axis xyz="0 0 1"/>
    <parent link="link"/>
    <origin rpy="0 0 0" xyz="0 0 0.2"/>
    <child link="link2"/>
    <dynamics damping="0.1"/>
  </joint>
  <link name="link">
    <inertial>
      <mass value="10"/>
      <origin xyz="0 0 0"/>
      <inertia ixx="1.0" ixy="0.0" ixz="0.0" iyy="0.1" iyz="0.0" izz="0.1"/>
    </inertial>
    <visual>
      <origin rpy="0 0 1" xyz="0 0 0"/>
      <geometry>
        <box size="0.2 1.0 0.2"/>
      </geometry>
    </visual>
    <collision>
      <origin rpy="0 0 1" xyz="0 0 0"/>
      <geometry>
        <box size="0.2 1.0 0.2"/>
      </geometry>
    </collision>
  </link>
  <gazebo reference="link">
    <material>Gazebo/GrassFloor</material>
    <turnGravityOff>true</turnGravityOff>
  </gazebo>
  <link name="link2">
		<inertial>
			<mass value="1" />
			<inertia ixx="1.0" ixy="0.0" ixz="0.0"
                     iyy="0.1" iyz="0.0"
                     izz="0.1" />                     
			</inertial>
    <visual>
      <origin rpy="0 0 1" xyz="0 0 0"/>
      <geometry>
        <box size="0.2 1.0 0.2"/>
      </geometry>
    </visual>
    <collision>
      <origin rpy="0 0 1" xyz="0 0 0"/>
      <geometry>
        <box size="0.2 1.0 0.2"/>
      </geometry>
    </collision>
  </link>
  <gazebo reference="link2">
    <material>Gazebo/WhiteEmissive</material>
    <turnGravityOff>true</turnGravityOff>
  </gazebo>
</robot>
